Workbook
Name PARAM_L_ING01: 'PARAM'!$E$10
Name PARAM_L_ING02: 'PARAM'!$E$11
Name PARAM_L_ING03: 'PARAM'!$E$12
Name PARAM_L_ING04: 'PARAM'!$E$13
Name PARAM_k_ING01: 'PARAM'!$E$14
Name PARAM_k_ING02: 'PARAM'!$E$15
Name PARAM_k_ING03: 'PARAM'!$E$16
Name PARAM_k_ING04: 'PARAM'!$E$17
Name PARAM_x0_ING01: 'PARAM'!$E$18
Name PARAM_x0_ING02: 'PARAM'!$E$19
Name PARAM_x0_ING03: 'PARAM'!$E$20
Name PARAM_x0_ING04: 'PARAM'!$E$21

Sheet START
B1: GE/BS 販売予測エンジン（Excel版）
B2: GE_BS_Forecast_Engine.xlsx | Phase 1-1 初期版
B4: シート名 | C4: 内容
B5: START | C5: 本ガイドシート（読み取り専用）
B6: PARAM | C6: 全パラメータ一覧（ユーザー編集）
B7: M_TherapeuticArea | C7: 疾患領域マスタ
B8: M_Ingredient | C8: 成分マスタ
B9: M_Product | C9: 製品マスタ
B10: M_SKU | C10: SKUマスタ
B11: M_Events | C11: 制度イベントマスタ
B12: M_FXRate | C12: 為替レートマスタ
B13: D_IQVIA | C13: IQVIA市場データ（Power Query取込）
B14: D_SellIn | C14: 自社Sell-inデータ
B15: D_SellOut | C15: 自社Sell-outデータ
... B24: LOG | C24: パラメータ変更履歴（VBA自動記録）
B26: ■ 月次更新手順
B27: ① CSVデータを docs/sample_data/ に配置
B28: ② [データ] → [すべて更新] で Power Query を実行
B29: ③ PARAM シートでパラメータを確認・調整
B30: ④ Ctrl+Alt+F9 でブック全体を再計算
B31: ⑤ Power BI (.pbix) を開いて [更新] をクリック

Sheet PARAM
B1: PARAM ― パラメータ管理シート
B2: セクション | C2: パラメータ | D2: 対象 | E2: 値（入力） | F2: 単位 | G2: 備考
B3: 【 薬価 】
B4: 薬価 | C4: 次回改定予定月 | E4: 2026-04 | F4: 年-月 | G4: 次回改定の発効月
B5: 薬価 | C5: 改定率（ING01） | D5: ING01 | E5: -0.055 | F5: % | G5: 過去実績平均値
B6: 薬価 | C6: 改定率（ING02） | D6: ING02 | E6: -0.062 | F6: % | G6: 過去実績平均値
B7: 薬価 | C7: 改定率（ING03） | D7: ING03 | E7: -0.048 | F7: % | G7: 過去実績平均値
B8: 薬価 | C8: 改定率（ING04） | D8: ING04 | E8: -0.07 | F8: % | G8: 過去実績平均値
B9: 【 浸透率 】
B10: 浸透率 | C10: 浸透率上限L（ING01） | D10: ING01 | E10: 0.87 | F10: 0〜1 | G10: Solverフィッティング結果
B11: 浸透率 | C11: 浸透率上限L（ING02） | D11: ING02 | E11: 0.83 | F11: 0〜1 | G11: Solverフィッティング結果
B12: 浸透率 | C12: 浸透率上限L（ING03） | D12: ING03 | E12: 0.58 | F12: 0〜1 | G12: Solverフィッティング結果
B13: 浸透率 | C13: 浸透率上限L（ING04） | D13: ING04 | E13: 0.42 | F13: 0〜1 | G13: Solverフィッティング結果
B14: 浸透率 | C14: 立ち上がり速度k（ING01） | D14: ING01 | E14: 0.1 | F14: 正の実数 | G14: Solverフィッティング結果
B15: 浸透率 | C15: 立ち上がり速度k（ING02） | D15: ING02 | E15: 0.1 | F15: 正の実数 | G15: Solverフィッティング結果
B16: 浸透率 | C16: 立ち上がり速度k（ING03） | D16: ING03 | E16: 0.13 | F16: 正の実数 | G16: Solverフィッティング結果
B17: 浸透率 | C17: 立ち上がり速度k（ING04） | D17: ING04 | E17: 0.11 | F17: 正の実数 | G17: Solverフィッティング結果
B18: 浸透率 | C18: 変曲点x0（ING01） | D18: ING01 | E18: -25 | F18: 月数 | G18: 実績開始からの経過月
B19: 浸透率 | C19: 変曲点x0（ING02） | D19: ING02 | E19: -20 | F19: 月数 | G19: 実績開始からの経過月
B20: 浸透率 | C20: 変曲点x0（ING03） | D20: ING03 | E20: 16 | F20: 月数 | G20: 実績開始からの経過月
B21: 浸透率 | C21: 変曲点x0（ING04） | D21: ING04 | E21: 20 | F21: 月数 | G21: 実績開始からの経過月
B22: 【 市場 】
B23: 市場 | C23: 疾患領域市場成長率（TA01） | D23: TA01 | E23: 0.015 | F23: %/年 | G23: 代謝・内分泌領域
B24: 市場 | C24: 疾患領域市場成長率（TA02） | D24: TA02 | E24: 0.01 | F24: %/年 | G24: 循環器領域
B25: 市場 | C25: 疾患領域市場成長率（TA03） | D25: TA03 | E25: 0.008 | F25: %/年 | G25: 血液領域
B26: 市場 | C26: 疾患領域市場成長率（TA04） | D26: TA04 | E26: 0.025 | F26: %/年 | G26: 免疫領域
B27: 【 競合 】
B28: 競合 | C28: 新規競合参入時期（ING01） | D28: ING01 | E28: 2026-10 | F28: 年-月 | G28: 手動入力
B29: 競合 | C29: 想定競合シェア（ING01） | D29: ING01 | E29: 0.05 | F29: % | G29: 参入後の最大シェア
B30: 競合 | C30: 新規競合参入時期（ING02） | D30: ING02 | F30: 年-月 | G30: 未定の場合は空欄
B31: 競合 | C31: 想定競合シェア（ING02） | D31: ING02 | F31: % | G31: 未定の場合は空欄
B32: 【 在庫 】
B33: 在庫 | C33: 適正在庫日数（卸A） | D33: 卸A | E33: 30 | F33: 日 | G33: 実測平均
B34: 在庫 | C34: 適正在庫日数（卸B） | D34: 卸B | E34: 28 | F34: 日 | G34: 実測平均
B35: 在庫 | C35: 適正在庫日数（卸C） | D35: 卸C | E35: 32 | F35: 日 | G35: 実測平均
B36: 在庫 | C36: 改定前積み増し率 | E36: 0.15 | F36: % | G36: 薬価改定前の卸積み増し率
B37: 在庫 | C37: 改定後調整率 | E37: -0.1 | F37: % | G37: 改定後の在庫取り崩し率
B38: 【 SKUミックス 】
B39: SKUミックス | C39: SKU0101 トレンド係数 | D39: SKU0101 | F39: 自動算出 | G39: TREND関数の結果を上書き可
B40: SKUミックス | C40: SKU0102 トレンド係数 | D40: SKU0102 | F40: 自動算出 | G40: TREND関数の結果を上書き可
...

Sheet M_TherapeuticArea
A1: therapeutic_area_id | B1: name
A2: TA01 | B2: 代謝・内分泌領域
A3: TA02 | B3: 循環器領域
A4: TA03 | B4: 腫瘍支持療法領域
A5: TA04 | B5: 免疫炎症領域

Sheet M_Ingredient
A1: ingredient_id | B1: therapeutic_area_id | C1: name | D1: drug_type
A2: ING01 | B2: TA01 | C2: メトホルミン塩酸塩 | D2: generic
A3: ING02 | B3: TA02 | C3: アトルバスタチン | D3: generic
A4: ING03 | B4: TA03 | C4: フィルグラスチム | D4: biosimilar
A5: ING04 | B5: TA04 | C5: インフリキシマブ | D5: biosimilar

Sheet M_Product
A1: product_id | B1: ingredient_id | C1: product_name | D1: type
A2: PROD01 | B2: ING01 | C2: メトグルコGE「サンド」 | D2: generic
A3: PROD02 | B3: ING02 | C3: アトルバスタチンOD錠「サンド」 | D3: generic
A4: PROD03 | B4: ING03 | C4: フィルグラスチムBS注「サンド」 | D4: biosimilar
A5: PROD04 | B5: ING04 | C5: インフリキシマブBS点滴静注用「サンド」 | D5: biosimilar

Sheet M_SKU
A1: sku_id | B1: product_id | C1: package_form | D1: package_size | E1: strength | F1: unit | G1: jan_code | H1: launch_date
A2: SKU0101 | B2: PROD01 | C2: PTP | D2: 100錠/シート | E2: 250mg | F2: 錠 | G2: 4987001010101 | H2: 2018-04-01
A3: SKU0102 | B3: PROD01 | C3: バラ包装 | D3: 500錠/瓶 | E3: 250mg | F3: 錠 | G3: 4987001010102 | H3: 2018-04-01
A4: SKU0201 | B4: PROD02 | C4: PTP | D4: 100錠/シート | E4: 10mg | F4: 錠 | G4: 4987002020201 | H4: 2015-06-01
A5: SKU0202 | B5: PROD02 | C5: PTP | D5: 100錠/シート | E5: 20mg | F5: 錠 | G5: 4987002020202 | H5: 2015-06-01
A6: SKU0301 | B6: PROD03 | C6: バイアル | D6: 1本/箱 | E6: 75μg/0.3mL | F6: 本 | G6: 4987003030301 | H6: 2021-09-01
A7: SKU0302 | B7: PROD03 | C7: バイアル | D7: 1本/箱 | E7: 150μg/0.5mL | F7: 本 | G7: 4987003030302 | H7: 2021-09-01
A8: SKU0401 | B8: PROD04 | C8: バイアル | D8: 1本/箱 | E8: 100mg | F8: 本 | G8: 4987004040401 | H8: 2022-01-01

Sheet M_Events
A1: event_date | B1: event_type | C1: impact_scope | D1: impact_target | E1: impact_parameter | F1: impact_value | G1: effect_lag_months | H1: memo
A2: 2024-04 | B2: 通常薬価改定 | C2: 全製品 | D2: price | E2: price_change_rate | F2: -0.055 | G2: 0 | H2: NHI薬価改定（ダミー想定値）
A3: 2025-04 | B3: 中間年改定 | C3: 全製品 | D3: price | E3: price_change_rate | F3: -0.03 | G3: 0 | H3: NHI薬価改定（ダミー想定値）
A4: 2026-04 | B4: 通常薬価改定 | C4: 全製品 | D4: price | E4: price_change_rate | F4: -0.06 | G4: 0 | H4: NHI薬価改定（ダミー想定値）
A5: 2026-06 | B5: バイオ後続品使用促進策強化 | C5: 後発品対象 | D5: penetration | E5: pen_L_delta | F5: 0.05 | G5: 3 | H5: 浸透率上限+5pp（3ヶ月で漸増）
A6: 2026-06 | B6: バイオ後続品使用促進策強化 | C6: 後発品対象 | D6: penetration | E6: pen_k_delta | F6: 0.02 | G6: 3 | H6: 立ち上がり速度+0.02（3ヶ月で漸増）

Sheet M_FXRate
A1: rate_type | B1: period | C1: jpy_per_usd | D1: updated_by | E1: updated_at
A2: historical | B2: 2023-01 | C2: 130.5 | D2: system | E2: 2026-06-19
A3: historical | B3: 2023-04 | C3: 133.1 | D3: system | E3: 2026-06-19
A4: historical | B4: 2023-07 | C4: 141.8 | D4: system | E4: 2026-06-19
A5: historical | B5: 2023-10 | C5: 149.2 | D5: system | E5: 2026-06-19
A6: historical | B6: 2024-01 | C6: 148 | D6: system | E6: 2026-06-19
A7: historical | B7: 2024-04 | C7: 151.9 | D7: system | E7: 2026-06-19
A8: historical | B8: 2024-07 | C8: 153.2 | D8: system | E8: 2026-06-19
A9: historical | B9: 2024-10 | C9: 150.1 | D9: system | E9: 2026-06-19
A10: historical | B10: 2025-01 | C10: 155 | D10: system | E10: 2026-06-19
A11: historical | B11: 2025-04 | C11: 148.3 | D11: system | E11: 2026-06-19
A12: historical | B12: 2025-07 | C12: 145 | D12: system | E12: 2026-06-19
A13: historical | B13: 2025-10 | C13: 149.7 | D13: system | E13: 2026-06-19
... A16: forecast_assumption | B16: 2026-06 | C16: 148 | D16: system | E16: 2026-06-19

Sheet D_IQVIA
A1: period | B1: therapeutic_area | C1: ingredient_name | D1: manufacturer_type | E1: product_name | F1: formulation | G1: sales_units | H1: unit_price_jpy | I1: sales_amount_jpy | J1: generic_biosimilar_penetration_rate
A2: 2023-01 | B2: 代謝・内分泌領域 | C2: メトホルミン塩酸塩 | D2: オリジナル | E2: メトグルコ（オリジナル） | F2: 錠 | G2: 124593 | H2: 13 | I2: 1614720 | J2: 0.7936
A3: 2023-01 | B3: 代謝・内分泌領域 | C3: メトホルミン塩酸塩 | D3: 自社 | E3: メトグルコGE「サンド」（自社合計） | F3: 錠 | G3: 65873 | H3: 9.6 | I3: 632385 | J3: 0.7936
A4: 2023-01 | B4: 代謝・内分泌領域 | C4: メトホルミン塩酸塩 | D4: 競合A | E4: 競合A社製品 | F4: 錠 | G4: 238914 | H4: 9.2 | I4: 2204075 | J4: 0.7936
A5: 2023-01 | B5: 代謝・内分泌領域 | C5: メトホルミン塩酸塩 | D5: 競合B | E5: 競合B社製品 | F5: 錠 | G5: 174277 | H5: 9.3 | I5: 1629485 | J5: 0.7936
A6: 2023-02 | B6: 代謝・内分泌領域 | C6: メトホルミン塩酸塩 | D6: オリジナル | E6: メトグルコ（オリジナル） | F6: 錠 | G6: 116400 | H6: 13 | I6: 1508543 | J6: 0.8067
A7: 2023-02 | B7: 代謝・内分泌領域 | C7: メトホルミン塩酸塩 | D7: 自社 | E7: メトグルコGE「サンド」（自社合計） | F7: 錠 | G7: 63452 | H7: 9.6 | I7: 609141 | J7: 0.8067
A8: 2023-02 | B8: 代謝・内分泌領域 | C8: メトホルミン塩酸塩 | D8: 競合A | E8: 競合A社製品 | F8: 錠 | G8: 221447 | H8: 9.8 | I8: 2163285 | J8: 0.8067
A9: 2023-02 | B9: 代謝・内分泌領域 | C9: メトホルミン塩酸塩 | D9: 競合B | E9: 競合B社製品 | F9: 錠 | G9: 200833 | H9: 9.7 | I9: 1957987 | J9: 0.8067
A10: 2023-03 | B10: 代謝・内分泌領域 | C10: メトホルミン塩酸塩 | D10: オリジナル | E10: メトグルコ（オリジナル） | F10: 錠 | G10: 112810 | H10: 13 | I10: 1462016 | J10: 0.8265
A11: 2023-03 | B11: 代謝・内分泌領域 | C11: メトホルミン塩酸塩 | D11: 自社 | E11: メトグルコGE「サンド」（自社合計） | F11: 錠 | G11: 73226 | H11: 9.6 | I11: 702966 | J11: 0.8265
A12: 2023-03 | B12: 代謝・内分泌領域 | C12: メトホルミン塩酸塩 | D12: 競合A | E12: 競合A社製品 | F12: 錠 | G12: 243297 | H12: 9.7 | I12: 2352878 | J12: 0.8265
A13: 2023-03 | B13: 代謝・内分泌領域 | C13: メトホルミン塩酸塩 | D13: 競合B | E13: 競合B社製品 | F13: 錠 | G13: 220814 | H13: 9.4 | I13: 2079165 | J13: 0.8265
... A657: 2026-05 | B657: 免疫炎症領域 | C657: インフリキシマブ | D657: 競合B | E657: 競合B社製品 | F657: 注射剤 | G657: 534 | H657: 31475.8 | I657: 16820061 | J657: 0.3825

Sheet D_SellIn
A1: period | B1: sku_id | C1: product_name | D1: distributor | E1: quantity | F1: amount_jpy
A2: 2023-01 | B2: SKU0101 | C2: メトグルコGE「サンド」 | D2: 卸A | E2: 14429 | F2: 138515
A3: 2023-01 | B3: SKU0101 | C3: メトグルコGE「サンド」 | D3: 卸B | E3: 9914 | F3: 95170
A4: 2023-01 | B4: SKU0101 | C4: メトグルコGE「サンド」 | D4: 卸C | E4: 5135 | F4: 49296
A5: 2023-02 | B5: SKU0101 | C5: メトグルコGE「サンド」 | D5: 卸A | E5: 13653 | F5: 131067
A6: 2023-02 | B6: SKU0101 | C6: メトグルコGE「サンド」 | D6: 卸B | E6: 8535 | F6: 81933
A7: 2023-02 | B7: SKU0101 | C7: メトグルコGE「サンド」 | D7: 卸C | E7: 4917 | F7: 47207
A8: 2023-03 | B8: SKU0101 | C8: メトグルコGE「サンド」 | D8: 卸A | E8: 18067 | F8: 173441
A9: 2023-03 | B9: SKU0101 | C9: メトグルコGE「サンド」 | D9: 卸B | E9: 10892 | F9: 104563
A10: 2023-03 | B10: SKU0101 | C10: メトグルコGE「サンド」 | D10: 卸C | E10: 6950 | F10: 66720
A11: 2023-04 | B11: SKU0101 | C11: メトグルコGE「サンド」 | D11: 卸A | E11: 13000 | F11: 124796
A12: 2023-04 | B12: SKU0101 | C12: メトグルコGE「サンド」 | D12: 卸B | E12: 8345 | F12: 80111
A13: 2023-04 | B13: SKU0101 | C13: メトグルコGE「サンド」 | D13: 卸C | E13: 4565 | F13: 43820
... A862: 2026-05 | B862: SKU0401 | C862: インフリキシマブBS点滴静注用「サンド」 | D862: 卸C | E862: 125 | F862: 3872287

Sheet D_SellOut
A1: period | B1: sku_id | C1: product_name | D1: facility_type | E1: quantity | F1: amount_jpy
A2: 2023-01 | B2: SKU0101 | C2: メトグルコGE「サンド」 | D2: 調剤薬局 | E2: 16487 | F2: 158273
A3: 2023-01 | B3: SKU0101 | C3: メトグルコGE「サンド」 | D3: 病院 | E3: 9062 | F3: 86991
A4: 2023-01 | B4: SKU0101 | C4: メトグルコGE「サンド」 | D4: 診療所 | E4: 4259 | F4: 40888
A5: 2023-01 | B5: SKU0102 | C5: メトグルコGE「サンド」 | D5: 調剤薬局 | E5: 20125 | F5: 193196
A6: 2023-01 | B6: SKU0102 | C6: メトグルコGE「サンド」 | D6: 病院 | E6: 10770 | F6: 103396
A7: 2023-01 | B7: SKU0102 | C7: メトグルコGE「サンド」 | D7: 診療所 | E7: 5356 | F7: 51416
A8: 2023-02 | B8: SKU0101 | C8: メトグルコGE「サンド」 | D8: 調剤薬局 | E8: 16267 | F8: 156161
A9: 2023-02 | B9: SKU0101 | C9: メトグルコGE「サンド」 | D9: 病院 | E9: 9031 | F9: 86695
A10: 2023-02 | B10: SKU0101 | C10: メトグルコGE「サンド」 | D10: 診療所 | E10: 4556 | F10: 43740
A11: 2023-02 | B11: SKU0102 | C11: メトグルコGE「サンド」 | D11: 調剤薬局 | E11: 19797 | F11: 190053
A12: 2023-02 | B12: SKU0102 | C12: メトグルコGE「サンド」 | D12: 病院 | E12: 10355 | F12: 99403
A13: 2023-02 | B13: SKU0102 | C13: メトグルコGE「サンド」 | D13: 診療所 | E13: 5249 | F13: 50393
... A739: 2026-05 | B739: SKU0401 | C739: インフリキシマブBS点滴静注用「サンド」 | D739: クリニック(注射対応) | E739: 92 | F739: 2866171

Sheet D_Inventory
A1: period | B1: sku_id | C1: product_name | D1: distributor | E1: ending_inventory_qty | F1: ending_inventory_amount_jpy
A2: 2023-01 | B2: SKU0101 | C2: メトグルコGE「サンド」 | D2: 卸A | E2: 9490 | F2: 91100
A3: 2023-01 | B3: SKU0101 | C3: メトグルコGE「サンド」 | D3: 卸B | E3: 8302 | F3: 79695
A4: 2023-01 | B4: SKU0101 | C4: メトグルコGE「サンド」 | D4: 卸C | E4: 4999 | F4: 47992
A5: 2023-02 | B5: SKU0101 | C5: メトグルコGE「サンド」 | D5: 卸A | E5: 8689 | F5: 83410
A6: 2023-02 | B6: SKU0101 | C6: メトグルコGE「サンド」 | D6: 卸B | E6: 7646 | F6: 73406
A7: 2023-02 | B7: SKU0101 | C7: メトグルコGE「サンド」 | D7: 卸C | E7: 4773 | F7: 45819
A8: 2023-03 | B8: SKU0101 | C8: メトグルコGE「サンド」 | D8: 卸A | E8: 10315 | F8: 99026
A9: 2023-03 | B9: SKU0101 | C9: メトグルコGE「サンド」 | D9: 卸B | E9: 8383 | F9: 80475
A10: 2023-03 | B10: SKU0101 | C10: メトグルコGE「サンド」 | D10: 卸C | E10: 5878 | F10: 56426
A11: 2023-04 | B11: SKU0101 | C11: メトグルコGE「サンド」 | D11: 卸A | E11: 9136 | F11: 87704
A12: 2023-04 | B12: SKU0101 | C12: メトグルコGE「サンド」 | D12: 卸B | E12: 7323 | F12: 70302
A13: 2023-04 | B13: SKU0101 | C13: メトグルコGE「サンド」 | D13: 卸C | E13: 5118 | F13: 49133
... A862: 2026-05 | B862: SKU0401 | C862: インフリキシマブBS点滴静注用「サンド」 | D862: 卸C | E862: 80 | F862: 2472342

Sheet C_MarketForecast
A1: C_MarketForecast ― Step1: 成分別市場サイズ予測（FORECAST.ETS, 季節性=12, 信頼区間80%/95%）
A2: 【 ING01 メトホルミン塩酸塩 】
A3: period | B3: total_units（実績） | C3: total_amount_jpy（実績） | D3: fc_units（ETS） | E3: fc_units_lower80 | F3: fc_units_upper80 | G3: fc_units_lower95 | H3: fc_units_upper95 | I3: fc_amount_jpy（ETS） | J3: 備考
A4: 2023-01 | B4: 603657 | C4: 6080665 | J4: ← 実績開始
A5: 2023-02 | B5: 602132 | C5: 6238956
A6: 2023-03 | B6: 650147 | C6: 6597025
A7: 2023-04 | B7: 581746 | C7: 5983081
A8: 2023-05 | B8: 597230 | C8: 6126517
A9: 2023-06 | B9: 628818 | C9: 6481613
A10: 2023-07 | B10: 602213 | C10: 6191874
A11: 2023-08 | B11: 596147 | C11: 6095399
A12: 2023-09 | B12: 613003 | C12: 6132687
A13: 2023-10 | B13: 599697 | C13: 6078304
A14: 2023-11 | B14: 585598 | C14: 5995057
A15: 2023-12 | B15: 602366 | C15: 6001459
A16: 2024-01 | B16: 596034 | C16: 5999600
... A44: 2026-05 | B44: 613389 | C44: 5341965
A45: 2026-06 | D45: =FORECAST.ETS(A45,$B$4:$B$44,$A$4:$A$44,12,1) | E45: =FORECAST.ETS(A45,$B$4:$B$44,$A$4:$A$44,12,1)-FORECAST.ETS.CONFINT(A45,$B$4:$B$44,$A$4:$A$44,0.8,12,1) | F45: =FORECAST.ETS(A45,$B$4:$B$44,$A$4:$A$44,12,1)+FORECAST.ETS.CONFINT(A45,$B$4:$B$44,$A$4:$A$44,0.8,12,1) | G45: =FORECAST.ETS(A45,$B$4:$B$44,$A$4:$A$44,12,1)-FORECAST.ETS.CONFINT(A45,$B$4:$B$44,$A$4:$A$44,0.95,12,1) | H45: =FORECAST.ETS(A45,$B$4:$B$44,$A$4:$A$44,12,1)+FORECAST.ETS.CONFINT(A45,$B$4:$B$44,$A$4:$A$44,0.95,12,1) | I45: =FORECAST.ETS(A45,$C$4:$C$44,$A$4:$A$44,12,1) | J45: ← 予測開始 (2026-06)
A46: 2026-07 | D46: =FORECAST.ETS(A46,$B$4:$B$44,$A$4:$A$44,12,1) | E46: =FORECAST.ETS(A46,$B$4:$B$44,$A$4:$A$44,12,1)-FORECAST.ETS.CONFINT(A46,$B$4:$B$44,$A$4:$A$44,0.8,12,1) | F46: =FORECAST.ETS(A46,$B$4:$B$44,$A$4:$A$44,12,1)+FORECAST.ETS.CONFINT(A46,$B$4:$B$44,$A$4:$A$44,0.8,12,1) | G46: =FORECAST.ETS(A46,$B$4:$B$44,$A$4:$A$44,12,1)-FORECAST.ETS.CONFINT(A46,$B$4:$B$44,$A$4:$A$44,0.95,12,1) | H46: =FORECAST.ETS(A46,$B$4:$B$44,$A$4:$A$44,12,1)+FORECAST.ETS.CONFINT(A46,$B$4:$B$44,$A$4:$A$44,0.95,12,1) | I46: =FORECAST.ETS(A46,$C$4:$C$44,$A$4:$A$44,12,1)
A47: 2026-08 | D47: =FORECAST.ETS(A47,$B$4:$B$44,$A$4:$A$44,12,1) | E47: =FORECAST.ETS(A47,$B$4:$B$44,$A$4:$A$44,12,1)-FORECAST.ETS.CONFINT(A47,$B$4:$B$44,$A$4:$A$44,0.8,12,1) | F47: =FORECAST.ETS(A47,$B$4:$B$44,$A$4:$A$44,12,1)+FORECAST.ETS.CONFINT(A47,$B$4:$B$44,$A$4:$A$44,0.8,12,1) | G47: =FORECAST.ETS(A47,$B$4:$B$44,$A$4:$A$44,12,1)-FORECAST.ETS.CONFINT(A47,$B$4:$B$44,$A$4:$A$44,0.95,12,1) | H47: =FORECAST.ETS(A47,$B$4:$B$44,$A$4:$A$44,12,1)+FORECAST.ETS.CONFINT(A47,$B$4:$B$44,$A$4:$A$44,0.95,12,1) | I47: =FORECAST.ETS(A47,$C$4:$C$44,$A$4:$A$44,12,1)
A48: 2026-09 | D48: =FORECAST.ETS(A48,$B$4:$B$44,$A$4:$A$44,12,1) | E48: =FORECAST.ETS(A48,$B$4:$B$44,$A$4:$A$44,12,1)-FORECAST.ETS.CONFINT(A48,$B$4:$B$44,$A$4:$A$44,0.8,12,1) | F48: =FORECAST.ETS(A48,$B$4:$B$44,$A$4:$A$44,12,1)+FORECAST.ETS.CONFINT(A48,$B$4:$B$44,$A$4:$A$44,0.8,12,1) | G48: =FORECAST.ETS(A48,$B$4:$B$44,$A$4:$A$44,12,1)-FORECAST.ETS.CONFINT(A48,$B$4:$B$44,$A$4:$A$44,0.95,12,1) | H48: =FORECAST.ETS(A48,$B$4:$B$44,$A$4:$A$44,12,1)+FORECAST.ETS.CONFINT(A48,$B$4:$B$44,$A$4:$A$44,0.95,12,1) | I48: =FORECAST.ETS(A48,$C$4:$C$44,$A$4:$A$44,12,1)
A49: 2026-10 | D49: =FORECAST.ETS(A49,$B$4:$B$44,$A$4:$A$44,12,1) | E49: =FORECAST.ETS(A49,$B$4:$B$44,$A$4:$A$44,12,1)-FORECAST.ETS.CONFINT(A49,$B$4:$B$44,$A$4:$A$44,0.8,12,1) | F49: =FORECAST.ETS(A49,$B$4:$B$44,$A$4:$A$44,12,1)+FORECAST.ETS.CONFINT(A49,$B$4:$B$44,$A$4:$A$44,0.8,12,1) | G49: =FORECAST.ETS(A49,$B$4:$B$44,$A$4:$A$44,12,1)-FORECAST.ETS.CONFINT(A49,$B$4:$B$44,$A$4:$A$44,0.95,12,1) | H49: =FORECAST.ETS(A49,$B$4:$B$44,$A$4:$A$44,12,1)+FORECAST.ETS.CONFINT(A49,$B$4:$B$44,$A$4:$A$44,0.95,12,1) | I49: =FORECAST.ETS(A49,$C$4:$C$44,$A$4:$A$44,12,1)
A50: 2026-11 | D50: =FORECAST.ETS(A50,$B$4:$B$44,$A$4:$A$44,12,1) | E50: =FORECAST.ETS(A50,$B$4:$B$44,$A$4:$A$44,12,1)-FORECAST.ETS.CONFINT(A50,$B$4:$B$44,$A$4:$A$44,0.8,12,1) | F50: =FORECAST.ETS(A50,$B$4:$B$44,$A$4:$A$44,12,1)+FORECAST.ETS.CONFINT(A50,$B$4:$B$44,$A$4:$A$44,0.8,12,1) | G50: =FORECAST.ETS(A50,$B$4:$B$44,$A$4:$A$44,12,1)-FORECAST.ETS.CONFINT(A50,$B$4:$B$44,$A$4:$A$44,0.95,12,1) | H50: =FORECAST.ETS(A50,$B$4:$B$44,$A$4:$A$44,12,1)+FORECAST.ETS.CONFINT(A50,$B$4:$B$44,$A$4:$A$44,0.95,12,1) | I50: =FORECAST.ETS(A50,$C$4:$C$44,$A$4:$A$44,12,1)
A51: 2026-12 | D51: =FORECAST.ETS(A51,$B$4:$B$44,$A$4:$A$44,12,1) | E51: =FORECAST.ETS(A51,$B$4:$B$44,$A$4:$A$44,12,1)-FORECAST.ETS.CONFINT(A51,$B$4:$B$44,$A$4:$A$44,0.8,12,1) | F51: =FORECAST.ETS(A51,$B$4:$B$44,$A$4:$A$44,12,1)+FORECAST.ETS.CONFINT(A51,$B$4:$B$44,$A$4:$A$44,0.8,12,1) | G51: =FORECAST.ETS(A51,$B$4:$B$44,$A$4:$A$44,12,1)-FORECAST.ETS.CONFINT(A51,$B$4:$B$44,$A$4:$A$44,0.95,12,1) | H51: =FORECAST.ETS(A51,$B$4:$B$44,$A$4:$A$44,12,1)+FORECAST.ETS.CONFINT(A51,$B$4:$B$44,$A$4:$A$44,0.95,12,1) | I51: =FORECAST.ETS(A51,$C$4:$C$44,$A$4:$A$44,12,1)
A52: 2027-01 | D52: =FORECAST.ETS(A52,$B$4:$B$44,$A$4:$A$44,12,1) | E52: =FORECAST.ETS(A52,$B$4:$B$44,$A$4:$A$44,12,1)-FORECAST.ETS.CONFINT(A52,$B$4:$B$44,$A$4:$A$44,0.8,12,1) | F52: =FORECAST.ETS(A52,$B$4:$B$44,$A$4:$A$44,12,1)+FORECAST.ETS.CONFINT(A52,$B$4:$B$44,$A$4:$A$44,0.8,12,1) | G52: =FORECAST.ETS(A52,$B$4:$B$44,$A$4:$A$44,12,1)-FORECAST.ETS.CONFINT(A52,$B$4:$B$44,$A$4:$A$44,0.95,12,1) | H52: =FORECAST.ETS(A52,$B$4:$B$44,$A$4:$A$44,12,1)+FORECAST.ETS.CONFINT(A52,$B$4:$B$44,$A$4:$A$44,0.95,12,1) | I52: =FORECAST.ETS(A52,$C$4:$C$44,$A$4:$A$44,12,1)
A53: 2027-02 | D53: =FORECAST.ETS(A53,$B$4:$B$44,$A$4:$A$44,12,1) | E53: =FORECAST.ETS(A53,$B$4:$B$44,$A$4:$A$44,12,1)-FORECAST.ETS.CONFINT(A53,$B$4:$B$44,$A$4:$A$44,0.8,12,1) | F53: =FORECAST.ETS(A53,$B$4:$B$44,$A$4:$A$44,12,1)+FORECAST.ETS.CONFINT(A53,$B$4:$B$44,$A$4:$A$44,0.8,12,1) | G53: =FORECAST.ETS(A53,$B$4:$B$44,$A$4:$A$44,12,1)-FORECAST.ETS.CONFINT(A53,$B$4:$B$44,$A$4:$A$44,0.95,12,1) | H53: =FORECAST.ETS(A53,$B$4:$B$44,$A$4:$A$44,12,1)+FORECAST.ETS.CONFINT(A53,$B$4:$B$44,$A$4:$A$44,0.95,12,1) | I53: =FORECAST.ETS(A53,$C$4:$C$44,$A$4:$A$44,12,1)
A54: 2027-03 | D54: =FORECAST.ETS(A54,$B$4:$B$44,$A$4:$A$44,12,1) | E54: =FORECAST.ETS(A54,$B$4:$B$44,$A$4:$A$44,12,1)-FORECAST.ETS.CONFINT(A54,$B$4:$B$44,$A$4:$A$44,0.8,12,1) | F54: =FORECAST.ETS(A54,$B$4:$B$44,$A$4:$A$44,12,1)+FORECAST.ETS.CONFINT(A54,$B$4:$B$44,$A$4:$A$44,0.8,12,1) | G54: =FORECAST.ETS(A54,$B$4:$B$44,$A$4:$A$44,12,1)-FORECAST.ETS.CONFINT(A54,$B$4:$B$44,$A$4:$A$44,0.95,12,1) | H54: =FORECAST.ETS(A54,$B$4:$B$44,$A$4:$A$44,12,1)+FORECAST.ETS.CONFINT(A54,$B$4:$B$44,$A$4:$A$44,0.95,12,1) | I54: =FORECAST.ETS(A54,$C$4:$C$44,$A$4:$A$44,12,1)
A55: 2027-04 | D55: =FORECAST.ETS(A55,$B$4:$B$44,$A$4:$A$44,12,1) | E55: =FORECAST.ETS(A55,$B$4:$B$44,$A$4:$A$44,12,1)-FORECAST.ETS.CONFINT(A55,$B$4:$B$44,$A$4:$A$44,0.8,12,1) | F55: =FORECAST.ETS(A55,$B$4:$B$44,$A$4:$A$44,12,1)+FORECAST.ETS.CONFINT(A55,$B$4:$B$44,$A$4:$A$44,0.8,12,1) | G55: =FORECAST.ETS(A55,$B$4:$B$44,$A$4:$A$44,12,1)-FORECAST.ETS.CONFINT(A55,$B$4:$B$44,$A$4:$A$44,0.95,12,1) | H55: =FORECAST.ETS(A55,$B$4:$B$44,$A$4:$A$44,12,1)+FORECAST.ETS.CONFINT(A55,$B$4:$B$44,$A$4:$A$44,0.95,12,1) | I55: =FORECAST.ETS(A55,$C$4:$C$44,$A$4:$A$44,12,1)
A56: 2027-05 | D56: =FORECAST.ETS(A56,$B$4:$B$44,$A$4:$A$44,12,1) | E56: =FORECAST.ETS(A56,$B$4:$B$44,$A$4:$A$44,12,1)-FORECAST.ETS.CONFINT(A56,$B$4:$B$44,$A$4:$A$44,0.8,12,1) | F56: =FORECAST.ETS(A56,$B$4:$B$44,$A$4:$A$44,12,1)+FORECAST.ETS.CONFINT(A56,$B$4:$B$44,$A$4:$A$44,0.8,12,1) | G56: =FORECAST.ETS(A56,$B$4:$B$44,$A$4:$A$44,12,1)-FORECAST.ETS.CONFINT(A56,$B$4:$B$44,$A$4:$A$44,0.95,12,1) | H56: =FORECAST.ETS(A56,$B$4:$B$44,$A$4:$A$44,12,1)+FORECAST.ETS.CONFINT(A56,$B$4:$B$44,$A$4:$A$44,0.95,12,1) | I56: =FORECAST.ETS(A56,$C$4:$C$44,$A$4:$A$44,12,1)
A57: 2027-06 | D57: =FORECAST.ETS(A57,$B$4:$B$44,$A$4:$A$44,12,1) | E57: =FORECAST.ETS(A57,$B$4:$B$44,$A$4:$A$44,12,1)-FORECAST.ETS.CONFINT(A57,$B$4:$B$44,$A$4:$A$44,0.8,12,1) | F57: =FORECAST.ETS(A57,$B$4:$B$44,$A$4:$A$44,12,1)+FORECAST.ETS.CONFINT(A57,$B$4:$B$44,$A$4:$A$44,0.8,12,1) | G57: =FORECAST.ETS(A57,$B$4:$B$44,$A$4:$A$44,12,1)-FORECAST.ETS.CONFINT(A57,$B$4:$B$44,$A$4:$A$44,0.95,12,1) | H57: =FORECAST.ETS(A57,$B$4:$B$44,$A$4:$A$44,12,1)+FORECAST.ETS.CONFINT(A57,$B$4:$B$44,$A$4:$A$44,0.95,12,1) | I57: =FORECAST.ETS(A57,$C$4:$C$44,$A$4:$A$44,12,1)
... A80: 2029-05 | D80: =FORECAST.ETS(A80,$B$4:$B$44,$A$4:$A$44,12,1) | E80: =FORECAST.ETS(A80,$B$4:$B$44,$A$4:$A$44,12,1)-FORECAST.ETS.CONFINT(A80,$B$4:$B$44,$A$4:$A$44,0.8,12,1) | F80: =FORECAST.ETS(A80,$B$4:$B$44,$A$4:$A$44,12,1)+FORECAST.ETS.CONFINT(A80,$B$4:$B$44,$A$4:$A$44,0.8,12,1) | G80: =FORECAST.ETS(A80,$B$4:$B$44,$A$4:$A$44,12,1)-FORECAST.ETS.CONFINT(A80,$B$4:$B$44,$A$4:$A$44,0.95,12,1) | H80: =FORECAST.ETS(A80,$B$4:$B$44,$A$4:$A$44,12,1)+FORECAST.ETS.CONFINT(A80,$B$4:$B$44,$A$4:$A$44,0.95,12,1) | I80: =FORECAST.ETS(A80,$C$4:$C$44,$A$4:$A$44,12,1)
A83: 【 ING02 アトルバスタチン 】
A84: period | B84: total_units（実績） | C84: total_amount_jpy（実績） | D84: fc_units（ETS） | E84: fc_units_lower80 | F84: fc_units_upper80 | G84: fc_units_lower95 | H84: fc_units_upper95 | I84: fc_amount_jpy（ETS） | J84: 備考
A85: 2023-01 | B85: 342323 | C85: 6700380 | J85: ← 実績開始
A86: 2023-02 | B86: 362402 | C86: 7147821
A87: 2023-03 | B87: 377614 | C87: 7420240
A88: 2023-04 | B88: 336471 | C88: 6558047
A89: 2023-05 | B89: 346096 | C89: 6834004
A90: 2023-06 | B90: 346090 | C90: 6722209
A91: 2023-07 | B91: 358270 | C91: 6966086
...

Sheet C_Penetration
A1: C_Penetration ― Step2: GE/BS 浸透率予測（ロジスティック曲線）
A2: 数式: penetration(t) = L / (1 + EXP(-k*(t-x0))) | 調整済: LAG=3ヶ月で線形に立ち上がるイベント反映 | PARAMシートで L/k/x0 を変更すると自動再計算
A3: 【 ING01 メトホルミン塩酸塩 】 L=PARAM_L_ING01 k=PARAM_k_ING01 x0=PARAM_x0_ING01
A4: period | B4: month_index | C4: actual_penetration | D4: logistic_fitted（base） | E4: forecast_excluded | F4: forecast_adjusted（制度変更反映） | G4: 備考
A5: 2023-01 | B5: 0 | C5: 0.7936 | D5: =PARAM!$E$10/(1+EXP(-PARAM!$E$14*(B5-PARAM!$E$18))) | G5: ← 実績開始 (month_index=0)
A6: 2023-02 | B6: 1 | C6: 0.8067 | D6: =PARAM!$E$10/(1+EXP(-PARAM!$E$14*(B6-PARAM!$E$18)))
A7: 2023-03 | B7: 2 | C7: 0.8265 | D7: =PARAM!$E$10/(1+EXP(-PARAM!$E$14*(B7-PARAM!$E$18)))
A8: 2023-04 | B8: 3 | C8: 0.8196 | D8: =PARAM!$E$10/(1+EXP(-PARAM!$E$14*(B8-PARAM!$E$18)))
A9: 2023-05 | B9: 4 | C9: 0.8211 | D9: =PARAM!$E$10/(1+EXP(-PARAM!$E$14*(B9-PARAM!$E$18)))
A10: 2023-06 | B10: 5 | C10: 0.8247 | D10: =PARAM!$E$10/(1+EXP(-PARAM!$E$14*(B10-PARAM!$E$18)))
A11: 2023-07 | B11: 6 | C11: 0.8241 | D11: =PARAM!$E$10/(1+EXP(-PARAM!$E$14*(B11-PARAM!$E$18)))
A12: 2023-08 | B12: 7 | C12: 0.8382 | D12: =PARAM!$E$10/(1+EXP(-PARAM!$E$14*(B12-PARAM!$E$18)))
A13: 2023-09 | B13: 8 | C13: 0.8397 | D13: =PARAM!$E$10/(1+EXP(-PARAM!$E$14*(B13-PARAM!$E$18)))
A14: 2023-10 | B14: 9 | C14: 0.8355 | D14: =PARAM!$E$10/(1+EXP(-PARAM!$E$14*(B14-PARAM!$E$18)))
A15: 2023-11 | B15: 10 | C15: 0.8411 | D15: =PARAM!$E$10/(1+EXP(-PARAM!$E$14*(B15-PARAM!$E$18)))
A16: 2023-12 | B16: 11 | C16: 0.8422 | D16: =PARAM!$E$10/(1+EXP(-PARAM!$E$14*(B16-PARAM!$E$18)))
A17: 2024-01 | B17: 12 | C17: 0.854 | D17: =PARAM!$E$10/(1+EXP(-PARAM!$E$14*(B17-PARAM!$E$18)))
... A45: 2026-05 | B45: 40 | C45: 0.8678 | D45: =PARAM!$E$10/(1+EXP(-PARAM!$E$14*(B45-PARAM!$E$18)))
A46: 2026-06 | B46: 41 | D46: =PARAM!$E$10/(1+EXP(-PARAM!$E$14*(B46-PARAM!$E$18))) | E46: =PARAM!$E$10/(1+EXP(-PARAM!$E$14*(B46-PARAM!$E$18))) | F46: =(PARAM!$E$10+0.05*MIN(MAX((B46-41)/3,0),1))/(1+EXP(-(PARAM!$E$14+0.02*MIN(MAX((B46-41)/3,0),1))*(B46-PARAM!$E$18))) | G46: ← 予測開始 (month_index=41, 2026-06)
A47: 2026-07 | B47: 42 | D47: =PARAM!$E$10/(1+EXP(-PARAM!$E$14*(B47-PARAM!$E$18))) | E47: =PARAM!$E$10/(1+EXP(-PARAM!$E$14*(B47-PARAM!$E$18))) | F47: =(PARAM!$E$10+0.05*MIN(MAX((B47-41)/3,0),1))/(1+EXP(-(PARAM!$E$14+0.02*MIN(MAX((B47-41)/3,0),1))*(B47-PARAM!$E$18)))
A48: 2026-08 | B48: 43 | D48: =PARAM!$E$10/(1+EXP(-PARAM!$E$14*(B48-PARAM!$E$18))) | E48: =PARAM!$E$10/(1+EXP(-PARAM!$E$14*(B48-PARAM!$E$18))) | F48: =(PARAM!$E$10+0.05*MIN(MAX((B48-41)/3,0),1))/(1+EXP(-(PARAM!$E$14+0.02*MIN(MAX((B48-41)/3,0),1))*(B48-PARAM!$E$18)))
A49: 2026-09 | B49: 44 | D49: =PARAM!$E$10/(1+EXP(-PARAM!$E$14*(B49-PARAM!$E$18))) | E49: =PARAM!$E$10/(1+EXP(-PARAM!$E$14*(B49-PARAM!$E$18))) | F49: =(PARAM!$E$10+0.05*MIN(MAX((B49-41)/3,0),1))/(1+EXP(-(PARAM!$E$14+0.02*MIN(MAX((B49-41)/3,0),1))*(B49-PARAM!$E$18))) | G49: ← 制度イベント 全効果発効 (month_index=44, 2026-09)
A50: 2026-10 | B50: 45 | D50: =PARAM!$E$10/(1+EXP(-PARAM!$E$14*(B50-PARAM!$E$18))) | E50: =PARAM!$E$10/(1+EXP(-PARAM!$E$14*(B50-PARAM!$E$18))) | F50: =(PARAM!$E$10+0.05*MIN(MAX((B50-41)/3,0),1))/(1+EXP(-(PARAM!$E$14+0.02*MIN(MAX((B50-41)/3,0),1))*(B50-PARAM!$E$18)))
A51: 2026-11 | B51: 46 | D51: =PARAM!$E$10/(1+EXP(-PARAM!$E$14*(B51-PARAM!$E$18))) | E51: =PARAM!$E$10/(1+EXP(-PARAM!$E$14*(B51-PARAM!$E$18))) | F51: =(PARAM!$E$10+0.05*MIN(MAX((B51-41)/3,0),1))/(1+EXP(-(PARAM!$E$14+0.02*MIN(MAX((B51-41)/3,0),1))*(B51-PARAM!$E$18)))
A52: 2026-12 | B52: 47 | D52: =PARAM!$E$10/(1+EXP(-PARAM!$E$14*(B52-PARAM!$E$18))) | E52: =PARAM!$E$10/(1+EXP(-PARAM!$E$14*(B52-PARAM!$E$18))) | F52: =(PARAM!$E$10+0.05*MIN(MAX((B52-41)/3,0),1))/(1+EXP(-(PARAM!$E$14+0.02*MIN(MAX((B52-41)/3,0),1))*(B52-PARAM!$E$18)))
A53: 2027-01 | B53: 48 | D53: =PARAM!$E$10/(1+EXP(-PARAM!$E$14*(B53-PARAM!$E$18))) | E53: =PARAM!$E$10/(1+EXP(-PARAM!$E$14*(B53-PARAM!$E$18))) | F53: =(PARAM!$E$10+0.05*MIN(MAX((B53-41)/3,0),1))/(1+EXP(-(PARAM!$E$14+0.02*MIN(MAX((B53-41)/3,0),1))*(B53-PARAM!$E$18)))
A54: 2027-02 | B54: 49 | D54: =PARAM!$E$10/(1+EXP(-PARAM!$E$14*(B54-PARAM!$E$18))) | E54: =PARAM!$E$10/(1+EXP(-PARAM!$E$14*(B54-PARAM!$E$18))) | F54: =(PARAM!$E$10+0.05*MIN(MAX((B54-41)/3,0),1))/(1+EXP(-(PARAM!$E$14+0.02*MIN(MAX((B54-41)/3,0),1))*(B54-PARAM!$E$18)))
A55: 2027-03 | B55: 50 | D55: =PARAM!$E$10/(1+EXP(-PARAM!$E$14*(B55-PARAM!$E$18))) | E55: =PARAM!$E$10/(1+EXP(-PARAM!$E$14*(B55-PARAM!$E$18))) | F55: =(PARAM!$E$10+0.05*MIN(MAX((B55-41)/3,0),1))/(1+EXP(-(PARAM!$E$14+0.02*MIN(MAX((B55-41)/3,0),1))*(B55-PARAM!$E$18)))
A56: 2027-04 | B56: 51 | D56: =PARAM!$E$10/(1+EXP(-PARAM!$E$14*(B56-PARAM!$E$18))) | E56: =PARAM!$E$10/(1+EXP(-PARAM!$E$14*(B56-PARAM!$E$18))) | F56: =(PARAM!$E$10+0.05*MIN(MAX((B56-41)/3,0),1))/(1+EXP(-(PARAM!$E$14+0.02*MIN(MAX((B56-41)/3,0),1))*(B56-PARAM!$E$18)))
A57: 2027-05 | B57: 52 | D57: =PARAM!$E$10/(1+EXP(-PARAM!$E$14*(B57-PARAM!$E$18))) | E57: =PARAM!$E$10/(1+EXP(-PARAM!$E$14*(B57-PARAM!$E$18))) | F57: =(PARAM!$E$10+0.05*MIN(MAX((B57-41)/3,0),1))/(1+EXP(-(PARAM!$E$14+0.02*MIN(MAX((B57-41)/3,0),1))*(B57-PARAM!$E$18)))
A58: 2027-06 | B58: 53 | D58: =PARAM!$E$10/(1+EXP(-PARAM!$E$14*(B58-PARAM!$E$18))) | E58: =PARAM!$E$10/(1+EXP(-PARAM!$E$14*(B58-PARAM!$E$18))) | F58: =(PARAM!$E$10+0.05*MIN(MAX((B58-41)/3,0),1))/(1+EXP(-(PARAM!$E$14+0.02*MIN(MAX((B58-41)/3,0),1))*(B58-PARAM!$E$18)))
A59: 2027-07 | B59: 54 | D59: =PARAM!$E$10/(1+EXP(-PARAM!$E$14*(B59-PARAM!$E$18))) | E59: =PARAM!$E$10/(1+EXP(-PARAM!$E$14*(B59-PARAM!$E$18))) | F59: =(PARAM!$E$10+0.05*MIN(MAX((B59-41)/3,0),1))/(1+EXP(-(PARAM!$E$14+0.02*MIN(MAX((B59-41)/3,0),1))*(B59-PARAM!$E$18)))
A60: 2027-08 | B60: 55 | D60: =PARAM!$E$10/(1+EXP(-PARAM!$E$14*(B60-PARAM!$E$18))) | E60: =PARAM!$E$10/(1+EXP(-PARAM!$E$14*(B60-PARAM!$E$18))) | F60: =(PARAM!$E$10+0.05*MIN(MAX((B60-41)/3,0),1))/(1+EXP(-(PARAM!$E$14+0.02*MIN(MAX((B60-41)/3,0),1))*(B60-PARAM!$E$18)))
A61: 2027-09 | B61: 56 | D61: =PARAM!$E$10/(1+EXP(-PARAM!$E$14*(B61-PARAM!$E$18))) | E61: =PARAM!$E$10/(1+EXP(-PARAM!$E$14*(B61-PARAM!$E$18))) | F61: =(PARAM!$E$10+0.05*MIN(MAX((B61-41)/3,0),1))/(1+EXP(-(PARAM!$E$14+0.02*MIN(MAX((B61-41)/3,0),1))*(B61-PARAM!$E$18)))
... A81: 2029-05 | B81: 76 | D81: =PARAM!$E$10/(1+EXP(-PARAM!$E$14*(B81-PARAM!$E$18))) | E81: =PARAM!$E$10/(1+EXP(-PARAM!$E$14*(B81-PARAM!$E$18))) | F81: =(PARAM!$E$10+0.05*MIN(MAX((B81-41)/3,0),1))/(1+EXP(-(PARAM!$E$14+0.02*MIN(MAX((B81-41)/3,0),1))*(B81-PARAM!$E$18)))
A84: 【 ING02 アトルバスタチン 】 L=PARAM_L_ING02 k=PARAM_k_ING02 x0=PARAM_x0_ING02
A85: period | B85: month_index | C85: actual_penetration | D85: logistic_fitted（base） | E85: forecast_excluded | F85: forecast_adjusted（制度変更反映） | G85: 備考
A86: 2023-01 | B86: 0 | C86: 0.7494 | D86: =PARAM!$E$11/(1+EXP(-PARAM!$E$15*(B86-PARAM!$E$19))) | G86: ← 実績開始 (month_index=0)
A87: 2023-02 | B87: 1 | C87: 0.7296 | D87: =PARAM!$E$11/(1+EXP(-PARAM!$E$15*(B87-PARAM!$E$19)))
A88: 2023-03 | B88: 2 | C88: 0.7335 | D88: =PARAM!$E$11/(1+EXP(-PARAM!$E$15*(B88-PARAM!$E$19)))
...

Sheet C_ShareForecast
A1: C_ShareForecast ― Step3: 自社製品シェア予測（TREND + 競合パラメータ）
A3: ※ このシートは Phase 1-2 以降で数式・Python in Excel を実装します。

Sheet C_SKUMix
A1: C_SKUMix ― Step4: SKU構成比トレンド予測（TREND + 正規化）
A3: ※ このシートは Phase 1-2 以降で数式・Python in Excel を実装します。

Sheet C_Integrated
A1: C_Integrated ― Step5: 統合予測（シナリオ別 SKU×月次）
A3: ※ このシートは Phase 1-2 以降で数式・Python in Excel を実装します。

Sheet OUT_Adjusted
A1: period | B1: sku_id | C1: ingredient_id | D1: product_id | E1: scenario_axis1 | F1: scenario_axis2 | G1: sellout_forecast_units | H1: sellout_forecast_jpy | I1: sellout_forecast_usd | J1: sellin_forecast_units | K1: sellin_forecast_jpy | L1: sellin_forecast_usd
A3: ※ C_Integrated シート（Phase 1-5）の数式により自動生成されます。

Sheet OUT_Excluded
A1: period | B1: sku_id | C1: ingredient_id | D1: product_id | E1: scenario_axis1 | F1: scenario_axis2 | G1: sellout_forecast_units | H1: sellout_forecast_jpy | I1: sellout_forecast_usd | J1: sellin_forecast_units | K1: sellin_forecast_jpy | L1: sellin_forecast_usd
A3: ※ C_Integrated シート（Phase 1-5）の数式により自動生成されます。

Sheet LOG
A1: timestamp | B1: user | C1: sheet | D1: cell_address | E1: parameter_name | F1: old_value | G1: new_value
A3: ※ PARAM シートへの入力変更は VBA（Worksheet_Change）で自動記録されます。
